[2024-11-06 16:22:10,997][root][INFO] - ---------------------------------------------------------------
[2024-11-06 16:22:10,998][root][INFO] - Env:
CUDA_VISIBLE_DEVICES: null
PYTHONOPTIMIZE: null

[2024-11-06 16:22:10,998][root][INFO] - Command line args:

[2024-11-06 16:22:10,999][root][INFO] - ---------------------------------------------------------------
[2024-11-06 16:22:11,001][root][INFO] - Run config:
device: '4'
solver_fn:
  _target_: netket.optimizer.solver.cholesky
lr: 0.001
diag_shift: 1.0e-10
n_iter: 2000
chunk_size_jac: 2
chunk_size_vmap: 1
save_every: 3
base_path: /scratch/.amisery/grad_sample/
model:
  _target_: grad_sample.models.ising.TFI
  L: 3
  h: 1.0
ansatz:
  _target_: netket.models.RBM
  alpha: 1
  param_dtype: complex
task:
  _target_: grad_sample.tasks.fullsum_analysis.FullSumPruning

[2024-11-06 16:22:11,001][root][INFO] - ---------------------------------------------------------------
[2024-11-06 16:22:13,757][jax._src.xla_bridge][INFO] - Unable to initialize backend 'rocm': module 'jaxlib.xla_extension' has no attribute 'GpuAllocatorConfig'
[2024-11-06 16:22:13,759][jax._src.xla_bridge][INFO] - Unable to initialize backend 'tpu': INTERNAL: Failed to open libtpu.so: libtpu.so: cannot open shared object file: No such file or directory
[2024-11-06 16:22:23,983][root][CRITICAL] - Shapes must be 1D sequences of concrete values of integer type, got (Traced<ShapedArray(int64[], weak_type=True)>with<DynamicJaxprTrace(level=1/0)>,).
If using `jit`, try using `static_argnums` or applying `jit` to smaller subfunctions.
The error occurred while tracing the function scanned_fun at /scratch/.amisery/netket2/lib/python3.10/site-packages/jax/_src/lax/control_flow/loops.py:1945 for scan. This concrete value was not available in Python because it depends on the value of the argument loop_carry[0].
jax.errors.SimplifiedTraceback: For simplicity, JAX has removed its internal frames from the traceback of the following exception. Set JAX_TRACEBACK_FILTERING=off to include these.

The above exception was the direct cause of the following exception:

Traceback (most recent call last):
  File "/home/amisery/phd/tfi_gs_samples/grad_sample/src/grad_sample/main.py", line 50, in main
    task()
  File "/home/amisery/phd/tfi_gs_samples/grad_sample/src/grad_sample/tasks/fullsum_analysis.py", line 42, in __call__
    in_idx, fid_vals, dp_dist_ev, infid_ev = self.prune()
  File "/home/amisery/phd/tfi_gs_samples/grad_sample/src/grad_sample/tasks/fullsum_analysis.py", line 189, in prune
    dp_dist_ev, infid_ev = jax.lax.fori_loop(1, len(in_idx), lambda i,val: self.prune_for(i, val, in_idx), ([],[]))
  File "/home/amisery/phd/tfi_gs_samples/grad_sample/src/grad_sample/tasks/fullsum_analysis.py", line 189, in <lambda>
    dp_dist_ev, infid_ev = jax.lax.fori_loop(1, len(in_idx), lambda i,val: self.prune_for(i, val, in_idx), ([],[]))
  File "/home/amisery/phd/tfi_gs_samples/grad_sample/src/grad_sample/tasks/fullsum_analysis.py", line 176, in prune_for
    a,b = self.prune_to(i, in_idx)
  File "/home/amisery/phd/tfi_gs_samples/grad_sample/src/grad_sample/tasks/fullsum_analysis.py", line 171, in prune_to
    dp_sol = self.compute_change(jax.lax.dynamic_slice(in_idx, (0,), (i,)), vmap_version=False)
TypeError: Shapes must be 1D sequences of concrete values of integer type, got (Traced<ShapedArray(int64[], weak_type=True)>with<DynamicJaxprTrace(level=1/0)>,).
If using `jit`, try using `static_argnums` or applying `jit` to smaller subfunctions.
The error occurred while tracing the function scanned_fun at /scratch/.amisery/netket2/lib/python3.10/site-packages/jax/_src/lax/control_flow/loops.py:1945 for scan. This concrete value was not available in Python because it depends on the value of the argument loop_carry[0].
